Workbook
Name campania: Graphs!$D$6
Name departamento: Graphs!$E$22
Name Eje_deptos: _xlfn.ANCHORARRAY(Validation_Functions!$A$3)
Name Eje_Provincias: Validation_Functions!$G$4:$G$21
Name Ha_cosechada: _xlfn.ANCHORARRAY(Validation_Functions!$C$3)
Name Ha_semb: _xlfn.ANCHORARRAY(Validation_Functions!$B$3)
Name prov_hist: Historical!$G$27
Name provincia: Graphs!$M$6
Name Rendimiento_kgxha: _xlfn.ANCHORARRAY(Validation_Functions!$E$3)
Name SegmentaciónDeDatos_anio: #N/A
Name SegmentaciónDeDatos_campania: #N/A
Name SegmentaciónDeDatos_departamento_nombre: #N/A
Name SegmentaciónDeDatos_provincia_nombre: #N/A
Name SegmentaciónDeDatos_provincia_nombre1: #N/A
Name Tn_producidas: _xlfn.ANCHORARRAY(Validation_Functions!$D$3)

Sheet mani-serie-1927-2024
A1: id | B1: cultivo_nombre | C1: anio | D1: campania | E1: provincia_nombre | F1: provincia_id | G1: departamento_nombre | H1: departamento_id | I1: superficie_sembrada_ha | J1: superficie_cosechada_ha | K1: produccion_tm | L1: rendimiento_kgxha
A2: 1 | B2: maní | C2: 1927 | D2: 1927/1928 | E2: Chaco | F2: 22 | G2: Campo del Cielo | H2: 22105 | I2: 4213 | J2: 4213 | K2: 3160 | L2: 750
A3: 2 | B3: maní | C3: 1927 | D3: 1927/1928 | E3: Chaco | F3: 22 | G3: Napalpí | H3: 22049 | I3: 465 | J3: 465 | K3: 348 | L3: 750
A4: 3 | B4: maní | C4: 1927 | D4: 1927/1928 | E4: Chaco | F4: 22 | G4: Resistencia | H4: 22140 | I4: 192 | J4: 192 | K4: 144 | L4: 750
A5: 4 | B5: maní | C5: 1927 | D5: 1927/1928 | E5: Chaco | F5: 22 | G5: Coronel Martínez de Hoz | H5: 22084 | I5: 71 | J5: 71 | K5: 53 | L5: 750
A6: 5 | B6: maní | C6: 1927 | D6: 1927/1928 | E6: Chaco | F6: 22 | G6: Bermejo | H6: 22014 | I6: 36 | J6: 36 | K6: 27 | L6: 750
A7: 6 | B7: maní | C7: 1927 | D7: 1927/1928 | E7: Chaco | F7: 22 | G7: Tobas | H7: 22091 | I7: 33 | J7: 33 | K7: 25 | L7: 750
A8: 7 | B8: maní | C8: 1927 | D8: 1927/1928 | E8: Chaco | F8: 22 | G8: Tapenagá | H8: 22161 | I8: 24 | J8: 24 | K8: 18 | L8: 750
A9: 8 | B9: maní | C9: 1927 | D9: 1927/1928 | E9: Córdoba | F9: 14 | G9: Santa María | H9: 14147 | I9: 9800 | J9: 9800 | K9: 13720 | L9: 1400
A10: 9 | B10: maní | C10: 1927 | D10: 1927/1928 | E10: Córdoba | F10: 14 | G10: Río Segundo | H10: 14119 | I10: 9200 | J10: 9200 | K10: 13800 | L10: 1500
A11: 10 | B11: maní | C11: 1927 | D11: 1927/1928 | E11: Córdoba | F11: 14 | G11: Río Primero | H11: 14105 | I11: 1700 | J11: 1700 | K11: 1870 | L11: 1100
A12: 11 | B12: maní | C12: 1927 | D12: 1927/1928 | E12: Córdoba | F12: 14 | G12: Tercero Arriba | H12: 14161 | I12: 1100 | J12: 1100 | K12: 1650 | L12: 1500
A13: 12 | B13: maní | C13: 1927 | D13: 1927/1928 | E13: Córdoba | F13: 14 | G13: Colón | H13: 14021 | I13: 1000 | J13: 1000 | K13: 1300 | L13: 1300
... A15: 14 | B15: maní | C15: 1927 | D15: 1927/1928 | E15: Córdoba | F15: 14 | G15: Río Cuarto | H15: 14098 | I15: 12 | J15: 12 | K15: 12 | L15: 1000
A16: 15 | B16: maní | C16: 1927 | D16: 1927/1928 | E16: Corrientes | F16: 18 | G16: otros departamentos | I16: 500 | J16: 500 | K16: 350 | L16: 700
A17: 16 | B17: maní | C17: 1927 | D17: 1927/1928 | E17: Corrientes | F17: 18 | G17: Monte Caseros | H17: 18112 | I17: 410 | J17: 410 | K17: 328 | L17: 800
A18: 17 | B18: maní | C18: 1927 | D18: 1927/1928 | E18: Corrientes | F18: 18 | G18: Lavalle | H18: 18091 | I18: 350 | J18: 350 | K18: 245 | L18: 700
A19: 18 | B19: maní | C19: 1927 | D19: 1927/1928 | E19: Corrientes | F19: 18 | G19: Empedrado | H19: 18042 | I19: 300 | J19: 300 | K19: 360 | L19: 1200
A20: 19 | B20: maní | C20: 1927 | D20: 1927/1928 | E20: Corrientes | F20: 18 | G20: Esquina | H20: 18049 | I20: 300 | J20: 300 | K20: 300 | L20: 1000
A21: 20 | B21: maní | C21: 1927 | D21: 1927/1928 | E21: Corrientes | F21: 18 | G21: San Cosme | H21: 18133 | I21: 260 | J21: 260 | K21: 260 | L21: 1000
A22: 21 | B22: maní | C22: 1927 | D22: 1927/1928 | E22: Corrientes | F22: 18 | G22: San Martín | H22: 18147 | I22: 200 | J22: 200 | K22: 180 | L22: 900
A23: 22 | B23: maní | C23: 1927 | D23: 1927/1928 | E23: Corrientes | F23: 18 | G23: Bella Vista | H23: 18007 | I23: 170 | J23: 170 | K23: 119 | L23: 700
A24: 23 | B24: maní | C24: 1927 | D24: 1927/1928 | E24: Corrientes | F24: 18 | G24: Ituzaingó | H24: 18084 | I24: 150 | J24: 150 | K24: 75 | L24: 500
A25: 24 | B25: maní | C25: 1927 | D25: 1927/1928 | E25: Corrientes | F25: 18 | G25: Saladas | H25: 18126 | I25: 150 | J25: 150 | K25: 90 | L25: 600
A26: 25 | B26: maní | C26: 1927 | D26: 1927/1928 | E26: Corrientes | F26: 18 | G26: San Luis del Palmar | H26: 18140 | I26: 140 | J26: 140 | K26: 140 | L26: 1000
A27: 26 | B27: maní | C27: 1927 | D27: 1927/1928 | E27: Corrientes | F27: 18 | G27: Capital | H27: 18021 | I27: 134 | J27: 134 | K27: 67 | L27: 500
A28: 27 | B28: maní | C28: 1927 | D28: 1927/1928 | E28: Corrientes | F28: 18 | G28: Curuzu Cuatia | H28: 18035 | I28: 100 | J28: 100 | K28: 100 | L28: 1000
... A87: 86 | B87: maní | C87: 1928 | D87: 1928/1929 | E87: Corrientes | F87: 18 | G87: Saladas | H87: 18126 | I87: 200 | J87: 200 | K87: 140 | L87: 700
A88: 87 | B88: maní | C88: 1928 | D88: 1928/1929 | E88: Corrientes | F88: 18 | G88: otros departamentos | I88: 200 | J88: 200 | K88: 140 | L88: 700
A89: 88 | B89: maní | C89: 1928 | D89: 1928/1929 | E89: Corrientes | F89: 18 | G89: Bella Vista | H89: 18007 | I89: 180 | J89: 180 | K89: 108 | L89: 600
A90: 89 | B90: maní | C90: 1928 | D90: 1928/1929 | E90: Corrientes | F90: 18 | G90: Sauce | H90: 18175 | I90: 180 | J90: 180 | K90: 180 | L90: 1000
A91: 90 | B91: maní | C91: 1928 | D91: 1928/1929 | E91: Corrientes | F91: 18 | G91: Curuzu Cuatia | H91: 18035 | I91: 140 | J91: 140 | K91: 112 | L91: 800
A92: 91 | B92: maní | C92: 1928 | D92: 1928/1929 | E92: Corrientes | F92: 18 | G92: San Luis del Palmar | H92: 18140 | I92: 100 | J92: 100 | K92: 60 | L92: 600
A93: 92 | B93: maní | C93: 1928 | D93: 1928/1929 | E93: Corrientes | F93: 18 | G93: Santo Tomé | H93: 18168 | I93: 100 | J93: 100 | K93: 60 | L93: 600
A94: 93 | B94: maní | C94: 1928 | D94: 1928/1929 | E94: Entre Ríos | F94: 30 | G94: Federación | H94: 30028 | I94: 7600 | J94: 7365 | K94: 9575 | L94: 1300
A95: 94 | B95: maní | C95: 1928 | D95: 1928/1929 | E95: Entre Ríos | F95: 30 | G95: Concordia | H95: 30015 | I95: 3350 | J95: 3250 | K95: 3900 | L95: 1200
A96: 95 | B96: maní | C96: 1928 | D96: 1928/1929 | E96: Entre Ríos | F96: 30 | G96: Colón | H96: 30008 | I96: 420 | J96: 405 | K96: 445 | L96: 1100
A97: 96 | B97: maní | C97: 1928 | D97: 1928/1929 | E97: Formosa | F97: 34 | G97: Pilcomayo | H97: 34049 | I97: 80 | J97: 65 | K97: 13 | L97: 200
A98: 97 | B98: maní | C98: 1928 | D98: 1928/1929 | E98: Formosa | F98: 34 | G98: Pirané | H98: 34056 | I98: 11 | J98: 8 | K98: 2 | L98: 250
A99: 98 | B99: maní | C99: 1928 | D99: 1928/1929 | E99: Formosa | F99: 34 | G99: Patiño | H99: 34035 | I99: 5 | J99: 3 | K99: 1 | L99: 300
...

Sheet InDepth_Analysis
A1: Provincias | B1: Superficie sembrada | C1: Superficie cosechada | D1: Toneladas producidas | E1: Rendimiento Kg x Ha
A2: Córdoba | B2: 948586 | C2: 933417 | D2: 3172237 | E2: 178342
A3: 2019/2020 | B3: 306528 | C3: 305772 | D3: 1096907 | E3: 50110
A4: 2020/2021 | B4: 318284 | C4: 314214 | D4: 1021036 | E4: 65322
A5: 2021/2022 | B5: 323774 | C5: 313431 | D5: 1054294 | E5: 62910
A6: Buenos Aires | B6: 98403 | C6: 98274 | D6: 324553 | E6: 134300
A7: 2019/2020 | B7: 20510 | C7: 20402 | D7: 77456 | E7: 37899
A8: 2020/2021 | B8: 39009 | C8: 39009 | D8: 111171 | E8: 40800
A9: 2021/2022 | B9: 38884 | C9: 38863 | D9: 135926 | E9: 55601
A10: La Pampa | B10: 55914 | C10: 55114 | D10: 175413 | E10: 69630
A11: 2019/2020 | B11: 15850 | C11: 15550 | D11: 56105 | E11: 27600
A12: 2020/2021 | B12: 21372 | C12: 21172 | D12: 58706 | E12: 20600
A13: 2021/2022 | B13: 18692 | C13: 18392 | D13: 60602 | E13: 21430
... A38: Total general | B38: 1191822 | C38: 1175610 | D38: 3898840 | E38: 470053

Sheet Depts_Comparison
B11: Departamento | C11: Superficie sembrada | D11: Superficie cosechada
B12: Río Cuarto | C12: 324000 | D12: 324000
B13: 2021 | C13: 89000 | D13: 89000
B14: 2022 | C14: 69000 | D14: 69000
B15: 2023 | C15: 81000 | D15: 81000
B16: 2024 | C16: 85000 | D16: 85000
B17: General Villegas | C17: 57500 | D17: 57500
B18: 2021 | C18: 11000 | D18: 11000
B19: 2022 | C19: 17000 | D19: 17000
B20: 2023 | C20: 12000 | D20: 12000
B21: 2024 | C21: 17500 | D21: 17500
B22: Total general | C22: 381500 | D22: 381500

Sheet Validation_Functions
A2: DEPTOS | B2: HA_SEMBRADA | C2: HA_COSECHADA | D2: TN_PRODUCIDAS | E2: RENDIMIENTO_KGXHA | G2: Produccion por provincia
A3: {=_xlfn.CHOOSECOLS(_xlfn.TAKE(_xlfn._xlws.SORT(_xlfn._xlws.FILTER(Produccion_mani[], (Produccion_mani[provincia_nombre]=provincia)*(Produccion_mani[campania]=campania)), 9, 1),- 5),7)} -> Tercero Arriba | B3: {=_xlfn.CHOOSECOLS(_xlfn.TAKE(_xlfn._xlws.SORT(_xlfn._xlws.FILTER(Produccion_mani[], (Produccion_mani[provincia_nombre]=provincia)*(Produccion_mani[campania]=campania)), 9, 1), -5),9)} -> 18000 | C3: {=_xlfn.CHOOSECOLS(_xlfn.TAKE(_xlfn._xlws.SORT(_xlfn._xlws.FILTER(Produccion_mani[], (Produccion_mani[provincia_nombre]=provincia)*(Produccion_mani[campania]=campania)), 9, 1), -5),10)} -> 18000 | D3: {=_xlfn.CHOOSECOLS(_xlfn.TAKE(_xlfn._xlws.SORT(_xlfn._xlws.FILTER(Produccion_mani[], (Produccion_mani[provincia_nombre]=provincia)*(Produccion_mani[campania]=campania)), 9, 1), -5),11)} -> 63000 | E3: {=_xlfn.CHOOSECOLS(_xlfn.TAKE(_xlfn._xlws.SORT(_xlfn._xlws.FILTER(Produccion_mani[], (Produccion_mani[provincia_nombre]=provincia)*(Produccion_mani[campania]=campania)), 9, 1), -5),12)} -> 3500 | G3: provincias | H3: tn_historicas | I3: ha_sembradas_historicas | J3: ha_cosechadas_historicas | M3: PROMEDIOS
A4: Presidente Roque Sáenz Peña | B4: 23940 | C4: 23666 | D4: 82831 | E4: 3500 | G4: {=_xlfn.UNIQUE(Produccion_mani[provincia_nombre])} -> Chaco | H4: {=SUM(IF((Produccion_mani[provincia_nombre]=G4),Produccion_mani[produccion_tm]))} -> 24753 | I4: {=SUM(IF((Produccion_mani[provincia_nombre]=G4),Produccion_mani[superficie_sembrada_ha]))} -> 29354 | J4: {=SUM(IF((Produccion_mani[provincia_nombre]=G4),Produccion_mani[superficie_cosechada_ha]))} -> 26695 | K4: {=SUM(IF((Produccion_mani[provincia_nombre]=G4),Produccion_mani[rendimiento_kgxha]))} -> 227574 | M4: {=_xlfn.UNIQUE(Produccion_mani[provincia_nombre])} -> Chaco | N4: {=AVERAGE(IF((Produccion_mani[provincia_nombre]=G4),Produccion_mani[produccion_tm]))} -> 69.923729 | O4: {=AVERAGE(IF((Produccion_mani[provincia_nombre]=G4),Produccion_mani[superficie_sembrada_ha]))} -> 82.920904 | P4: {=AVERAGE(IF((Produccion_mani[provincia_nombre]=G4),Produccion_mani[superficie_cosechada_ha]))} -> 75.409605 | Q4: {=AVERAGE(IF((Produccion_mani[provincia_nombre]=G4),Produccion_mani[rendimiento_kgxha]))} -> 642.86441
A5: Juárez Celman | B5: 32500 | C5: 32500 | D5: 116675 | E5: 3590 | G5: Córdoba | H5: {=SUM(IF((Produccion_mani[provincia_nombre]=G5),Produccion_mani[produccion_tm]))} -> 34220930 | I5: {=SUM(IF((Produccion_mani[provincia_nombre]=G5),Produccion_mani[superficie_sembrada_ha]))} -> 20942037 | J5: {=SUM(IF((Produccion_mani[provincia_nombre]=G5),Produccion_mani[superficie_cosechada_ha]))} -> 20156675 | K5: {=SUM(IF((Produccion_mani[provincia_nombre]=G5),Produccion_mani[rendimiento_kgxha]))} -> 1787341 | M5: Córdoba | N5: {=AVERAGE(IF((Produccion_mani[provincia_nombre]=G5),Produccion_mani[produccion_tm]))} -> 28976.232 | O5: {=AVERAGE(IF((Produccion_mani[provincia_nombre]=G5),Produccion_mani[superficie_sembrada_ha]))} -> 17732.461 | P5: {=AVERAGE(IF((Produccion_mani[provincia_nombre]=G5),Produccion_mani[superficie_cosechada_ha]))} -> 17067.464 | Q5: {=AVERAGE(IF((Produccion_mani[provincia_nombre]=G5),Produccion_mani[rendimiento_kgxha]))} -> 1513.4132
A6: Río Cuarto | B6: 89000 | C6: 89000 | D6: 319510 | E6: 3590 | G6: Corrientes | H6: {=SUM(IF((Produccion_mani[provincia_nombre]=G6),Produccion_mani[produccion_tm]))} -> 66651 | I6: {=SUM(IF((Produccion_mani[provincia_nombre]=G6),Produccion_mani[superficie_sembrada_ha]))} -> 82657 | J6: {=SUM(IF((Produccion_mani[provincia_nombre]=G6),Produccion_mani[superficie_cosechada_ha]))} -> 69955 | K6: {=SUM(IF((Produccion_mani[provincia_nombre]=G6),Produccion_mani[rendimiento_kgxha]))} -> 787396 | M6: Corrientes | N6: {=AVERAGE(IF((Produccion_mani[provincia_nombre]=G6),Produccion_mani[produccion_tm]))} -> 66.651 | O6: {=AVERAGE(IF((Produccion_mani[provincia_nombre]=G6),Produccion_mani[superficie_sembrada_ha]))} -> 82.657 | P6: {=AVERAGE(IF((Produccion_mani[provincia_nombre]=G6),Produccion_mani[superficie_cosechada_ha]))} -> 69.955 | Q6: {=AVERAGE(IF((Produccion_mani[provincia_nombre]=G6),Produccion_mani[rendimiento_kgxha]))} -> 787.396
A7: General Roca | B7: 90060 | C7: 89878 | D7: 314573 | E7: 3500 | G7: Entre Ríos | H7: {=SUM(IF((Produccion_mani[provincia_nombre]=G7),Produccion_mani[produccion_tm]))} -> 186177 | I7: {=SUM(IF((Produccion_mani[provincia_nombre]=G7),Produccion_mani[superficie_sembrada_ha]))} -> 204725 | J7: {=SUM(IF((Produccion_mani[provincia_nombre]=G7),Produccion_mani[superficie_cosechada_ha]))} -> 174772 | K7: {=SUM(IF((Produccion_mani[provincia_nombre]=G7),Produccion_mani[rendimiento_kgxha]))} -> 140905 | M7: Entre Ríos | N7: {=AVERAGE(IF((Produccion_mani[provincia_nombre]=G7),Produccion_mani[produccion_tm]))} -> 921.66832 | O7: {=AVERAGE(IF((Produccion_mani[provincia_nombre]=G7),Produccion_mani[superficie_sembrada_ha]))} -> 1013.4901 | P7: {=AVERAGE(IF((Produccion_mani[provincia_nombre]=G7),Produccion_mani[superficie_cosechada_ha]))} -> 865.20792 | Q7: {=AVERAGE(IF((Produccion_mani[provincia_nombre]=G7),Produccion_mani[rendimiento_kgxha]))} -> 697.5495
G8: Formosa | H8: {=SUM(IF((Produccion_mani[provincia_nombre]=G8),Produccion_mani[produccion_tm]))} -> 21618 | I8: {=SUM(IF((Produccion_mani[provincia_nombre]=G8),Produccion_mani[superficie_sembrada_ha]))} -> 18510 | J8: {=SUM(IF((Produccion_mani[provincia_nombre]=G8),Produccion_mani[superficie_cosechada_ha]))} -> 17149 | K8: {=SUM(IF((Produccion_mani[provincia_nombre]=G8),Produccion_mani[rendimiento_kgxha]))} -> 274671 | M8: Formosa | N8: {=AVERAGE(IF((Produccion_mani[provincia_nombre]=G8),Produccion_mani[produccion_tm]))} -> 71.582781 | O8: {=AVERAGE(IF((Produccion_mani[provincia_nombre]=G8),Produccion_mani[superficie_sembrada_ha]))} -> 61.291391 | P8: {=AVERAGE(IF((Produccion_mani[provincia_nombre]=G8),Produccion_mani[superficie_cosechada_ha]))} -> 56.784768 | Q8: {=AVERAGE(IF((Produccion_mani[provincia_nombre]=G8),Produccion_mani[rendimiento_kgxha]))} -> 909.50662
G9: Jujuy | H9: {=SUM(IF((Produccion_mani[provincia_nombre]=G9),Produccion_mani[produccion_tm]))} -> 13910 | I9: {=SUM(IF((Produccion_mani[provincia_nombre]=G9),Produccion_mani[superficie_sembrada_ha]))} -> 11962 | J9: {=SUM(IF((Produccion_mani[provincia_nombre]=G9),Produccion_mani[superficie_cosechada_ha]))} -> 11429 | K9: {=SUM(IF((Produccion_mani[provincia_nombre]=G9),Produccion_mani[rendimiento_kgxha]))} -> 63070 | M9: Jujuy | N9: {=AVERAGE(IF((Produccion_mani[provincia_nombre]=G9),Produccion_mani[produccion_tm]))} -> 248.39286 | O9: {=AVERAGE(IF((Produccion_mani[provincia_nombre]=G9),Produccion_mani[superficie_sembrada_ha]))} -> 213.60714 | P9: {=AVERAGE(IF((Produccion_mani[provincia_nombre]=G9),Produccion_mani[superficie_cosechada_ha]))} -> 204.08929 | Q9: {=AVERAGE(IF((Produccion_mani[provincia_nombre]=G9),Produccion_mani[rendimiento_kgxha]))} -> 1126.25
G10: Misiones | H10: {=SUM(IF((Produccion_mani[provincia_nombre]=G10),Produccion_mani[produccion_tm]))} -> 20260 | I10: {=SUM(IF((Produccion_mani[provincia_nombre]=G10),Produccion_mani[superficie_sembrada_ha]))} -> 27464 | J10: {=SUM(IF((Produccion_mani[provincia_nombre]=G10),Produccion_mani[superficie_cosechada_ha]))} -> 22667 | K10: {=SUM(IF((Produccion_mani[provincia_nombre]=G10),Produccion_mani[rendimiento_kgxha]))} -> 543358 | M10: Misiones | N10: {=AVERAGE(IF((Produccion_mani[provincia_nombre]=G10),Produccion_mani[produccion_tm]))} -> 28.656294 | O10: {=AVERAGE(IF((Produccion_mani[provincia_nombre]=G10),Produccion_mani[superficie_sembrada_ha]))} -> 38.845827 | P10: {=AVERAGE(IF((Produccion_mani[provincia_nombre]=G10),Produccion_mani[superficie_cosechada_ha]))} -> 32.06082 | Q10: {=AVERAGE(IF((Produccion_mani[provincia_nombre]=G10),Produccion_mani[rendimiento_kgxha]))} -> 768.54031
G11: Santa Fe | H11: {=SUM(IF((Produccion_mani[provincia_nombre]=G11),Produccion_mani[produccion_tm]))} -> 528321 | I11: {=SUM(IF((Produccion_mani[provincia_nombre]=G11),Produccion_mani[superficie_sembrada_ha]))} -> 367795 | J11: {=SUM(IF((Produccion_mani[provincia_nombre]=G11),Produccion_mani[superficie_cosechada_ha]))} -> 323838 | K11: {=SUM(IF((Produccion_mani[provincia_nombre]=G11),Produccion_mani[rendimiento_kgxha]))} -> 319249 | M11: Santa Fe | N11: {=AVERAGE(IF((Produccion_mani[provincia_nombre]=G11),Produccion_mani[produccion_tm]))} -> 2238.6483 | O11: {=AVERAGE(IF((Produccion_mani[provincia_nombre]=G11),Produccion_mani[superficie_sembrada_ha]))} -> 1558.4534 | P11: {=AVERAGE(IF((Produccion_mani[provincia_nombre]=G11),Produccion_mani[superficie_cosechada_ha]))} -> 1372.1949 | Q11: {=AVERAGE(IF((Produccion_mani[provincia_nombre]=G11),Produccion_mani[rendimiento_kgxha]))} -> 1352.75
G12: Santiago del Estero | H12: {=SUM(IF((Produccion_mani[provincia_nombre]=G12),Produccion_mani[produccion_tm]))} -> 2754 | I12: {=SUM(IF((Produccion_mani[provincia_nombre]=G12),Produccion_mani[superficie_sembrada_ha]))} -> 3065 | J12: {=SUM(IF((Produccion_mani[provincia_nombre]=G12),Produccion_mani[superficie_cosechada_ha]))} -> 2600 | K12: {=SUM(IF((Produccion_mani[provincia_nombre]=G12),Produccion_mani[rendimiento_kgxha]))} -> 104417 | M12: Santiago del Estero | N12: {=AVERAGE(IF((Produccion_mani[provincia_nombre]=G12),Produccion_mani[produccion_tm]))} -> 20.25 | O12: {=AVERAGE(IF((Produccion_mani[provincia_nombre]=G12),Produccion_mani[superficie_sembrada_ha]))} -> 22.536765 | P12: {=AVERAGE(IF((Produccion_mani[provincia_nombre]=G12),Produccion_mani[superficie_cosechada_ha]))} -> 19.117647 | Q12: {=AVERAGE(IF((Produccion_mani[provincia_nombre]=G12),Produccion_mani[rendimiento_kgxha]))} -> 767.77206
G13: Tucumán | H13: {=SUM(IF((Produccion_mani[provincia_nombre]=G13),Produccion_mani[produccion_tm]))} -> 56633 | I13: {=SUM(IF((Produccion_mani[provincia_nombre]=G13),Produccion_mani[superficie_sembrada_ha]))} -> 58489 | J13: {=SUM(IF((Produccion_mani[provincia_nombre]=G13),Produccion_mani[superficie_cosechada_ha]))} -> 49058 | K13: {=SUM(IF((Produccion_mani[provincia_nombre]=G13),Produccion_mani[rendimiento_kgxha]))} -> 305269 | M13: Tucumán | N13: {=AVERAGE(IF((Produccion_mani[provincia_nombre]=G13),Produccion_mani[produccion_tm]))} -> 183.87338 | O13: {=AVERAGE(IF((Produccion_mani[provincia_nombre]=G13),Produccion_mani[superficie_sembrada_ha]))} -> 189.89935 | P13: {=AVERAGE(IF((Produccion_mani[provincia_nombre]=G13),Produccion_mani[superficie_cosechada_ha]))} -> 159.27922 | Q13: {=AVERAGE(IF((Produccion_mani[provincia_nombre]=G13),Produccion_mani[rendimiento_kgxha]))} -> 991.13312
G14: Catamarca | H14: {=SUM(IF((Produccion_mani[provincia_nombre]=G14),Produccion_mani[produccion_tm]))} -> 11537 | I14: {=SUM(IF((Produccion_mani[provincia_nombre]=G14),Produccion_mani[superficie_sembrada_ha]))} -> 8117 | J14: {=SUM(IF((Produccion_mani[provincia_nombre]=G14),Produccion_mani[superficie_cosechada_ha]))} -> 7677 | K14: {=SUM(IF((Produccion_mani[provincia_nombre]=G14),Produccion_mani[rendimiento_kgxha]))} -> 22081 | M14: Catamarca | N14: {=AVERAGE(IF((Produccion_mani[provincia_nombre]=G14),Produccion_mani[produccion_tm]))} -> 501.6087 | O14: {=AVERAGE(IF((Produccion_mani[provincia_nombre]=G14),Produccion_mani[superficie_sembrada_ha]))} -> 352.91304 | P14: {=AVERAGE(IF((Produccion_mani[provincia_nombre]=G14),Produccion_mani[superficie_cosechada_ha]))} -> 333.78261 | Q14: {=AVERAGE(IF((Produccion_mani[provincia_nombre]=G14),Produccion_mani[rendimiento_kgxha]))} -> 960.04348
G15: Salta | H15: {=SUM(IF((Produccion_mani[provincia_nombre]=G15),Produccion_mani[produccion_tm]))} -> 251121 | I15: {=SUM(IF((Produccion_mani[provincia_nombre]=G15),Produccion_mani[superficie_sembrada_ha]))} -> 200589 | J15: {=SUM(IF((Produccion_mani[provincia_nombre]=G15),Produccion_mani[superficie_cosechada_ha]))} -> 189877 | K15: {=SUM(IF((Produccion_mani[provincia_nombre]=G15),Produccion_mani[rendimiento_kgxha]))} -> 375429 | M15: Salta | N15: {=AVERAGE(IF((Produccion_mani[provincia_nombre]=G15),Produccion_mani[produccion_tm]))} -> 831.52649 | O15: {=AVERAGE(IF((Produccion_mani[provincia_nombre]=G15),Produccion_mani[superficie_sembrada_ha]))} -> 664.20199 | P15: {=AVERAGE(IF((Produccion_mani[provincia_nombre]=G15),Produccion_mani[superficie_cosechada_ha]))} -> 628.73179 | Q15: {=AVERAGE(IF((Produccion_mani[provincia_nombre]=G15),Produccion_mani[rendimiento_kgxha]))} -> 1243.1424
G16: San Juan | H16: {=SUM(IF((Produccion_mani[provincia_nombre]=G16),Produccion_mani[produccion_tm]))} -> 36 | I16: {=SUM(IF((Produccion_mani[provincia_nombre]=G16),Produccion_mani[superficie_sembrada_ha]))} -> 39 | J16: {=SUM(IF((Produccion_mani[provincia_nombre]=G16),Produccion_mani[superficie_cosechada_ha]))} -> 32 | K16: {=SUM(IF((Produccion_mani[provincia_nombre]=G16),Produccion_mani[rendimiento_kgxha]))} -> 9217 | M16: San Juan | N16: {=AVERAGE(IF((Produccion_mani[provincia_nombre]=G16),Produccion_mani[produccion_tm]))} -> 4 | O16: {=AVERAGE(IF((Produccion_mani[provincia_nombre]=G16),Produccion_mani[superficie_sembrada_ha]))} -> 4.3333333 | P16: {=AVERAGE(IF((Produccion_mani[provincia_nombre]=G16),Produccion_mani[superficie_cosechada_ha]))} -> 3.5555556 | Q16: {=AVERAGE(IF((Produccion_mani[provincia_nombre]=G16),Produccion_mani[rendimiento_kgxha]))} -> 1024.1111
G17: San Luis | H17: {=SUM(IF((Produccion_mani[provincia_nombre]=G17),Produccion_mani[produccion_tm]))} -> 717565 | I17: {=SUM(IF((Produccion_mani[provincia_nombre]=G17),Produccion_mani[superficie_sembrada_ha]))} -> 254411 | J17: {=SUM(IF((Produccion_mani[provincia_nombre]=G17),Produccion_mani[superficie_cosechada_ha]))} -> 243919 | K17: {=SUM(IF((Produccion_mani[provincia_nombre]=G17),Produccion_mani[rendimiento_kgxha]))} -> 294312 | M17: San Luis | N17: {=AVERAGE(IF((Produccion_mani[provincia_nombre]=G17),Produccion_mani[produccion_tm]))} -> 4752.0861 | O17: {=AVERAGE(IF((Produccion_mani[provincia_nombre]=G17),Produccion_mani[superficie_sembrada_ha]))} -> 1684.8411 | P17: {=AVERAGE(IF((Produccion_mani[provincia_nombre]=G17),Produccion_mani[superficie_cosechada_ha]))} -> 1615.3576 | Q17: {=AVERAGE(IF((Produccion_mani[provincia_nombre]=G17),Produccion_mani[rendimiento_kgxha]))} -> 1949.0861
G18: Mendoza | H18: {=SUM(IF((Produccion_mani[provincia_nombre]=G18),Produccion_mani[produccion_tm]))} -> 935 | I18: {=SUM(IF((Produccion_mani[provincia_nombre]=G18),Produccion_mani[superficie_sembrada_ha]))} -> 1759 | J18: {=SUM(IF((Produccion_mani[provincia_nombre]=G18),Produccion_mani[superficie_cosechada_ha]))} -> 1143 | K18: {=SUM(IF((Produccion_mani[provincia_nombre]=G18),Produccion_mani[rendimiento_kgxha]))} -> 26628 | M18: Mendoza | N18: {=AVERAGE(IF((Produccion_mani[provincia_nombre]=G18),Produccion_mani[produccion_tm]))} -> 27.5 | O18: {=AVERAGE(IF((Produccion_mani[provincia_nombre]=G18),Produccion_mani[superficie_sembrada_ha]))} -> 51.735294 | P18: {=AVERAGE(IF((Produccion_mani[provincia_nombre]=G18),Produccion_mani[superficie_cosechada_ha]))} -> 33.617647 | Q18: {=AVERAGE(IF((Produccion_mani[provincia_nombre]=G18),Produccion_mani[rendimiento_kgxha]))} -> 783.17647
G19: Buenos Aires | H19: {=SUM(IF((Produccion_mani[provincia_nombre]=G19),Produccion_mani[produccion_tm]))} -> 1069917 | I19: {=SUM(IF((Produccion_mani[provincia_nombre]=G19),Produccion_mani[superficie_sembrada_ha]))} -> 317539 | J19: {=SUM(IF((Produccion_mani[provincia_nombre]=G19),Produccion_mani[superficie_cosechada_ha]))} -> 317134 | K19: {=SUM(IF((Produccion_mani[provincia_nombre]=G19),Produccion_mani[rendimiento_kgxha]))} -> 410784 | M19: Buenos Aires | N19: {=AVERAGE(IF((Produccion_mani[provincia_nombre]=G19),Produccion_mani[produccion_tm]))} -> 7809.6131 | O19: {=AVERAGE(IF((Produccion_mani[provincia_nombre]=G19),Produccion_mani[superficie_sembrada_ha]))} -> 2317.8029 | P19: {=AVERAGE(IF((Produccion_mani[provincia_nombre]=G19),Produccion_mani[superficie_cosechada_ha]))} -> 2314.8467 | Q19: {=AVERAGE(IF((Produccion_mani[provincia_nombre]=G19),Produccion_mani[rendimiento_kgxha]))} -> 2998.4234
... G21: La Rioja | H21: {=SUM(IF((Produccion_mani[provincia_nombre]=G21),Produccion_mani[produccion_tm]))} -> 0 | I21: {=SUM(IF((Produccion_mani[provincia_nombre]=G21),Produccion_mani[superficie_sembrada_ha]))} -> 270 | J21: {=SUM(IF((Produccion_mani[provincia_nombre]=G21),Produccion_mani[superficie_cosechada_ha]))} -> 0 | K21: {=SUM(IF((Produccion_mani[provincia_nombre]=G21),Produccion_mani[rendimiento_kgxha]))} -> 0 | M21: La Rioja | N21: {=AVERAGE(IF((Produccion_mani[provincia_nombre]=G21),Produccion_mani[produccion_tm]))} -> 0 | O21: {=AVERAGE(IF((Produccion_mani[provincia_nombre]=G21),Produccion_mani[superficie_sembrada_ha]))} -> 270 | P21: {=AVERAGE(IF((Produccion_mani[provincia_nombre]=G21),Produccion_mani[superficie_cosechada_ha]))} -> 0 | Q21: {=AVERAGE(IF((Produccion_mani[provincia_nombre]=G21),Produccion_mani[rendimiento_kgxha]))} -> 0
A29: TN PROD X CAMP | B29: {=TRANSPOSE(_xlfn.ANCHORARRAY(A137))} -> Chaco | C29: Córdoba | D29: Corrientes | E29: Entre Ríos | F29: Formosa | G29: Jujuy | H29: Misiones | I29: Santa Fe | J29: Santiago del Estero | K29: Tucumán | L29: Catamarca | M29: Salta | N29: San Juan | O29: San Luis | P29: Mendoza | Q29: Buenos Aires | R29: La Pampa | S29: La Rioja
A30: {=_xlfn.UNIQUE(Produccion_mani[campania])} -> 1927/1928 | B30: {=SUM(IF((Produccion_mani[provincia_nombre]=B$29)*(Produccion_mani[campania]=A30),Produccion_mani[produccion_tm]))} -> 3775 | C30: {=SUM(IF((Produccion_mani[provincia_nombre]=C$29)*(Produccion_mani[campania]=A30),Produccion_mani[produccion_tm]))} -> 32742 | D30: {=SUM(IF((Produccion_mani[provincia_nombre]=D$29)*(Produccion_mani[campania]=A30),Produccion_mani[produccion_tm]))} -> 2724 | E30: {=SUM(IF((Produccion_mani[provincia_nombre]=E$29)*(Produccion_mani[campania]=A30),Produccion_mani[produccion_tm]))} -> 11640 | F30: {=SUM(IF((Produccion_mani[provincia_nombre]=F$29)*(Produccion_mani[campania]=A30),Produccion_mani[produccion_tm]))} -> 100 | G30: {=SUM(IF((Produccion_mani[provincia_nombre]=G$29)*(Produccion_mani[campania]=A30),Produccion_mani[produccion_tm]))} -> 27 | H30: {=SUM(IF((Produccion_mani[provincia_nombre]=H$29)*(Produccion_mani[campania]=A30),Produccion_mani[produccion_tm]))} -> 529 | I30: {=SUM(IF((Produccion_mani[provincia_nombre]=I$29)*(Produccion_mani[campania]=A30),Produccion_mani[produccion_tm]))} -> 12906 | J30: {=SUM(IF((Produccion_mani[provincia_nombre]=J$29)*(Produccion_mani[campania]=A30),Produccion_mani[produccion_tm]))} -> 98 | K30: {=SUM(IF((Produccion_mani[provincia_nombre]=K$29)*(Produccion_mani[campania]=A30),Produccion_mani[produccion_tm]))} -> 183 | L30: {=SUM(IF((Produccion_mani[provincia_nombre]=L$29)*(Produccion_mani[campania]=A30),Produccion_mani[produccion_tm]))} -> 0 | M30: {=SUM(IF((Produccion_mani[provincia_nombre]=M$29)*(Produccion_mani[campania]=A30),Produccion_mani[produccion_tm]))} -> 0 | N30: {=SUM(IF((Produccion_mani[provincia_nombre]=N$29)*(Produccion_mani[campania]=A30),Produccion_mani[produccion_tm]))} -> 0 | O30: {=SUM(IF((Produccion_mani[provincia_nombre]=O$29)*(Produccion_mani[campania]=A30),Produccion_mani[produccion_tm]))} -> 0 | P30: {=SUM(IF((Produccion_mani[provincia_nombre]=P$29)*(Produccion_mani[campania]=A30),Produccion_mani[produccion_tm]))} -> 0 | Q30: {=SUM(IF((Produccion_mani[provincia_nombre]=Q$29)*(Produccion_mani[campania]=A30),Produccion_mani[produccion_tm]))} -> 0 | R30: {=SUM(IF((Produccion_mani[provincia_nombre]=R$29)*(Produccion_mani[campania]=A30),Produccion_mani[produccion_tm]))} -> 0 | S30: {=SUM(IF((Produccion_mani[provincia_nombre]=S$29)*(Produccion_mani[campania]=A30),Produccion_mani[produccion_tm]))} -> 0
A31: 1928/1929 | B31: {=SUM(IF((Produccion_mani[provincia_nombre]=B$29)*(Produccion_mani[campania]=A31),Produccion_mani[produccion_tm]))} -> 1205 | C31: {=SUM(IF((Produccion_mani[provincia_nombre]=C$29)*(Produccion_mani[campania]=A31),Produccion_mani[produccion_tm]))} -> 11930 | D31: {=SUM(IF((Produccion_mani[provincia_nombre]=D$29)*(Produccion_mani[campania]=A31),Produccion_mani[produccion_tm]))} -> 2774 | E31: {=SUM(IF((Produccion_mani[provincia_nombre]=E$29)*(Produccion_mani[campania]=A31),Produccion_mani[produccion_tm]))} -> 13920 | F31: {=SUM(IF((Produccion_mani[provincia_nombre]=F$29)*(Produccion_mani[campania]=A31),Produccion_mani[produccion_tm]))} -> 16 | G31: {=SUM(IF((Produccion_mani[provincia_nombre]=G$29)*(Produccion_mani[campania]=A31),Produccion_mani[produccion_tm]))} -> 0 | H31: {=SUM(IF((Produccion_mani[provincia_nombre]=H$29)*(Produccion_mani[campania]=A31),Produccion_mani[produccion_tm]))} -> 611 | I31: {=SUM(IF((Produccion_mani[provincia_nombre]=I$29)*(Produccion_mani[campania]=A31),Produccion_mani[produccion_tm]))} -> 15568 | J31: {=SUM(IF((Produccion_mani[provincia_nombre]=J$29)*(Produccion_mani[campania]=A31),Produccion_mani[produccion_tm]))} -> 58 | K31: {=SUM(IF((Produccion_mani[provincia_nombre]=K$29)*(Produccion_mani[campania]=A31),Produccion_mani[produccion_tm]))} -> 34 | L31: {=SUM(IF((Produccion_mani[provincia_nombre]=L$29)*(Produccion_mani[campania]=A31),Produccion_mani[produccion_tm]))} -> 25 | M31: {=SUM(IF((Produccion_mani[provincia_nombre]=M$29)*(Produccion_mani[campania]=A31),Produccion_mani[produccion_tm]))} -> 45 | N31: {=SUM(IF((Produccion_mani[provincia_nombre]=N$29)*(Produccion_mani[campania]=A31),Produccion_mani[produccion_tm]))} -> 0 | O31: {=SUM(IF((Produccion_mani[provincia_nombre]=O$29)*(Produccion_mani[campania]=A31),Produccion_mani[produccion_tm]))} -> 0 | P31: {=SUM(IF((Produccion_mani[provincia_nombre]=P$29)*(Produccion_mani[campania]=A31),Produccion_mani[produccion_tm]))} -> 0 | Q31: {=SUM(IF((Produccion_mani[provincia_nombre]=Q$29)*(Produccion_mani[campania]=A31),Produccion_mani[produccion_tm]))} -> 0 | R31: {=SUM(IF((Produccion_mani[provincia_nombre]=R$29)*(Produccion_mani[campania]=A31),Produccion_mani[produccion_tm]))} -> 0 | S31: {=SUM(IF((Produccion_mani[provincia_nombre]=S$29)*(Produccion_mani[campania]=A31),Produccion_mani[produccion_tm]))} -> 0
A32: 1929/1930 | B32: {=SUM(IF((Produccion_mani[provincia_nombre]=B$29)*(Produccion_mani[campania]=A32),Produccion_mani[produccion_tm]))} -> 1200 | C32: {=SUM(IF((Produccion_mani[provincia_nombre]=C$29)*(Produccion_mani[campania]=A32),Produccion_mani[produccion_tm]))} -> 42730 | D32: {=SUM(IF((Produccion_mani[provincia_nombre]=D$29)*(Produccion_mani[campania]=A32),Produccion_mani[produccion_tm]))} -> 2334 | E32: {=SUM(IF((Produccion_mani[provincia_nombre]=E$29)*(Produccion_mani[campania]=A32),Produccion_mani[produccion_tm]))} -> 4972 | F32: {=SUM(IF((Produccion_mani[provincia_nombre]=F$29)*(Produccion_mani[campania]=A32),Produccion_mani[produccion_tm]))} -> 50 | G32: {=SUM(IF((Produccion_mani[provincia_nombre]=G$29)*(Produccion_mani[campania]=A32),Produccion_mani[produccion_tm]))} -> 0 | H32: {=SUM(IF((Produccion_mani[provincia_nombre]=H$29)*(Produccion_mani[campania]=A32),Produccion_mani[produccion_tm]))} -> 600 | I32: {=SUM(IF((Produccion_mani[provincia_nombre]=I$29)*(Produccion_mani[campania]=A32),Produccion_mani[produccion_tm]))} -> 13421 | J32: {=SUM(IF((Produccion_mani[provincia_nombre]=J$29)*(Produccion_mani[campania]=A32),Produccion_mani[produccion_tm]))} -> 50 | K32: {=SUM(IF((Produccion_mani[provincia_nombre]=K$29)*(Produccion_mani[campania]=A32),Produccion_mani[produccion_tm]))} -> 33 | L32: {=SUM(IF((Produccion_mani[provincia_nombre]=L$29)*(Produccion_mani[campania]=A32),Produccion_mani[produccion_tm]))} -> 20 | M32: {=SUM(IF((Produccion_mani[provincia_nombre]=M$29)*(Produccion_mani[campania]=A32),Produccion_mani[produccion_tm]))} -> 0 | N32: {=SUM(IF((Produccion_mani[provincia_nombre]=N$29)*(Produccion_mani[campania]=A32),Produccion_mani[produccion_tm]))} -> 0 | O32: {=SUM(IF((Produccion_mani[provincia_nombre]=O$29)*(Produccion_mani[campania]=A32),Produccion_mani[produccion_tm]))} -> 0 | P32: {=SUM(IF((Produccion_mani[provincia_nombre]=P$29)*(Produccion_mani[campania]=A32),Produccion_mani[produccion_tm]))} -> 0 | Q32: {=SUM(IF((Produccion_mani[provincia_nombre]=Q$29)*(Produccion_mani[campania]=A32),Produccion_mani[produccion_tm]))} -> 0 | R32: {=SUM(IF((Produccion_mani[provincia_nombre]=R$29)*(Produccion_mani[campania]=A32),Produccion_mani[produccion_tm]))} -> 0 | S32: {=SUM(IF((Produccion_mani[provincia_nombre]=S$29)*(Produccion_mani[campania]=A32),Produccion_mani[produccion_tm]))} -> 0
A33: 1930/1931 | B33: {=SUM(IF((Produccion_mani[provincia_nombre]=B$29)*(Produccion_mani[campania]=A33),Produccion_mani[produccion_tm]))} -> 3570 | C33: {=SUM(IF((Produccion_mani[provincia_nombre]=C$29)*(Produccion_mani[campania]=A33),Produccion_mani[produccion_tm]))} -> 34412 | D33: {=SUM(IF((Produccion_mani[provincia_nombre]=D$29)*(Produccion_mani[campania]=A33),Produccion_mani[produccion_tm]))} -> 2660 | E33: {=SUM(IF((Produccion_mani[provincia_nombre]=E$29)*(Produccion_mani[campania]=A33),Produccion_mani[produccion_tm]))} -> 7169 | F33: {=SUM(IF((Produccion_mani[provincia_nombre]=F$29)*(Produccion_mani[campania]=A33),Produccion_mani[produccion_tm]))} -> 25 | G33: {=SUM(IF((Produccion_mani[provincia_nombre]=G$29)*(Produccion_mani[campania]=A33),Produccion_mani[produccion_tm]))} -> 0 | H33: {=SUM(IF((Produccion_mani[provincia_nombre]=H$29)*(Produccion_mani[campania]=A33),Produccion_mani[produccion_tm]))} -> 860 | I33: {=SUM(IF((Produccion_mani[provincia_nombre]=I$29)*(Produccion_mani[campania]=A33),Produccion_mani[produccion_tm]))} -> 17321 | J33: {=SUM(IF((Produccion_mani[provincia_nombre]=J$29)*(Produccion_mani[campania]=A33),Produccion_mani[produccion_tm]))} -> 36 | K33: {=SUM(IF((Produccion_mani[provincia_nombre]=K$29)*(Produccion_mani[campania]=A33),Produccion_mani[produccion_tm]))} -> 390 | L33: {=SUM(IF((Produccion_mani[provincia_nombre]=L$29)*(Produccion_mani[campania]=A33),Produccion_mani[produccion_tm]))} -> 0 | M33: {=SUM(IF((Produccion_mani[provincia_nombre]=M$29)*(Produccion_mani[campania]=A33),Produccion_mani[produccion_tm]))} -> 0 | N33: {=SUM(IF((Produccion_mani[provincia_nombre]=N$29)*(Produccion_mani[campania]=A33),Produccion_mani[produccion_tm]))} -> 2 | O33: {=SUM(IF((Produccion_mani[provincia_nombre]=O$29)*(Produccion_mani[campania]=A33),Produccion_mani[produccion_tm]))} -> 0 | P33: {=SUM(IF((Produccion_mani[provincia_nombre]=P$29)*(Produccion_mani[campania]=A33),Produccion_mani[produccion_tm]))} -> 0 | Q33: {=SUM(IF((Produccion_mani[provincia_nombre]=Q$29)*(Produccion_mani[campania]=A33),Produccion_mani[produccion_tm]))} -> 0 | R33: {=SUM(IF((Produccion_mani[provincia_nombre]=R$29)*(Produccion_mani[campania]=A33),Produccion_mani[produccion_tm]))} -> 0 | S33: {=SUM(IF((Produccion_mani[provincia_nombre]=S$29)*(Produccion_mani[campania]=A33),Produccion_mani[produccion_tm]))} -> 0
A34: 1931/1932 | B34: {=SUM(IF((Produccion_mani[provincia_nombre]=B$29)*(Produccion_mani[campania]=A34),Produccion_mani[produccion_tm]))} -> 520 | C34: {=SUM(IF((Produccion_mani[provincia_nombre]=C$29)*(Produccion_mani[campania]=A34),Produccion_mani[produccion_tm]))} -> 43615 | D34: {=SUM(IF((Produccion_mani[provincia_nombre]=D$29)*(Produccion_mani[campania]=A34),Produccion_mani[produccion_tm]))} -> 3142 | E34: {=SUM(IF((Produccion_mani[provincia_nombre]=E$29)*(Produccion_mani[campania]=A34),Produccion_mani[produccion_tm]))} -> 3049 | F34: {=SUM(IF((Produccion_mani[provincia_nombre]=F$29)*(Produccion_mani[campania]=A34),Produccion_mani[produccion_tm]))} -> 18 | G34: {=SUM(IF((Produccion_mani[provincia_nombre]=G$29)*(Produccion_mani[campania]=A34),Produccion_mani[produccion_tm]))} -> 0 | H34: {=SUM(IF((Produccion_mani[provincia_nombre]=H$29)*(Produccion_mani[campania]=A34),Produccion_mani[produccion_tm]))} -> 1492 | I34: {=SUM(IF((Produccion_mani[provincia_nombre]=I$29)*(Produccion_mani[campania]=A34),Produccion_mani[produccion_tm]))} -> 5511 | J34: {=SUM(IF((Produccion_mani[provincia_nombre]=J$29)*(Produccion_mani[campania]=A34),Produccion_mani[produccion_tm]))} -> 38 | K34: {=SUM(IF((Produccion_mani[provincia_nombre]=K$29)*(Produccion_mani[campania]=A34),Produccion_mani[produccion_tm]))} -> 1250 | L34: {=SUM(IF((Produccion_mani[provincia_nombre]=L$29)*(Produccion_mani[campania]=A34),Produccion_mani[produccion_tm]))} -> 0 | M34: {=SUM(IF((Produccion_mani[provincia_nombre]=M$29)*(Produccion_mani[campania]=A34),Produccion_mani[produccion_tm]))} -> 0 | N34: {=SUM(IF((Produccion_mani[provincia_nombre]=N$29)*(Produccion_mani[campania]=A34),Produccion_mani[produccion_tm]))} -> 4 | O34: {=SUM(IF((Produccion_mani[provincia_nombre]=O$29)*(Produccion_mani[campania]=A34),Produccion_mani[produccion_tm]))} -> 24 | P34: {=SUM(IF((Produccion_mani[provincia_nombre]=P$29)*(Produccion_mani[campania]=A34),Produccion_mani[produccion_tm]))} -> 0 | Q34: {=SUM(IF((Produccion_mani[provincia_nombre]=Q$29)*(Produccion_mani[campania]=A34),Produccion_mani[produccion_tm]))} -> 0 | R34: {=SUM(IF((Produccion_mani[provincia_nombre]=R$29)*(Produccion_mani[campania]=A34),Produccion_mani[produccion_tm]))} -> 0 | S34: {=SUM(IF((Produccion_mani[provincia_nombre]=S$29)*(Produccion_mani[campania]=A34),Produccion_mani[produccion_tm]))} -> 0
A35: 1932/1933 | B35: {=SUM(IF((Produccion_mani[provincia_nombre]=B$29)*(Produccion_mani[campania]=A35),Produccion_mani[produccion_tm]))} -> 3575 | C35: {=SUM(IF((Produccion_mani[provincia_nombre]=C$29)*(Produccion_mani[campania]=A35),Produccion_mani[produccion_tm]))} -> 44022 | D35: {=SUM(IF((Produccion_mani[provincia_nombre]=D$29)*(Produccion_mani[campania]=A35),Produccion_mani[produccion_tm]))} -> 3936 | E35: {=SUM(IF((Produccion_mani[provincia_nombre]=E$29)*(Produccion_mani[campania]=A35),Produccion_mani[produccion_tm]))} -> 5890 | F35: {=SUM(IF((Produccion_mani[provincia_nombre]=F$29)*(Produccion_mani[campania]=A35),Produccion_mani[produccion_tm]))} -> 19 | G35: {=SUM(IF((Produccion_mani[provincia_nombre]=G$29)*(Produccion_mani[campania]=A35),Produccion_mani[produccion_tm]))} -> 16 | H35: {=SUM(IF((Produccion_mani[provincia_nombre]=H$29)*(Produccion_mani[campania]=A35),Produccion_mani[produccion_tm]))} -> 968 | I35: {=SUM(IF((Produccion_mani[provincia_nombre]=I$29)*(Produccion_mani[campania]=A35),Produccion_mani[produccion_tm]))} -> 17894 | J35: {=SUM(IF((Produccion_mani[provincia_nombre]=J$29)*(Produccion_mani[campania]=A35),Produccion_mani[produccion_tm]))} -> 110 | K35: {=SUM(IF((Produccion_mani[provincia_nombre]=K$29)*(Produccion_mani[campania]=A35),Produccion_mani[produccion_tm]))} -> 1834 | L35: {=SUM(IF((Produccion_mani[provincia_nombre]=L$29)*(Produccion_mani[campania]=A35),Produccion_mani[produccion_tm]))} -> 0 | M35: {=SUM(IF((Produccion_mani[provincia_nombre]=M$29)*(Produccion_mani[campania]=A35),Produccion_mani[produccion_tm]))} -> 2 | N35: {=SUM(IF((Produccion_mani[provincia_nombre]=N$29)*(Produccion_mani[campania]=A35),Produccion_mani[produccion_tm]))} -> 0 | O35: {=SUM(IF((Produccion_mani[provincia_nombre]=O$29)*(Produccion_mani[campania]=A35),Produccion_mani[produccion_tm]))} -> 21 | P35: {=SUM(IF((Produccion_mani[provincia_nombre]=P$29)*(Produccion_mani[campania]=A35),Produccion_mani[produccion_tm]))} -> 0 | Q35: {=SUM(IF((Produccion_mani[provincia_nombre]=Q$29)*(Produccion_mani[campania]=A35),Produccion_mani[produccion_tm]))} -> 0 | R35: {=SUM(IF((Produccion_mani[provincia_nombre]=R$29)*(Produccion_mani[campania]=A35),Produccion_mani[produccion_tm]))} -> 0 | S35: {=SUM(IF((Produccion_mani[provincia_nombre]=S$29)*(Produccion_mani[campania]=A35),Produccion_mani[produccion_tm]))} -> 0
A36: 1933/1934 | B36: {=SUM(IF((Produccion_mani[provincia_nombre]=B$29)*(Produccion_mani[campania]=A36),Produccion_mani[produccion_tm]))} -> 249 | C36: {=SUM(IF((Produccion_mani[provincia_nombre]=C$29)*(Produccion_mani[campania]=A36),Produccion_mani[produccion_tm]))} -> 77325 | D36: {=SUM(IF((Produccion_mani[provincia_nombre]=D$29)*(Produccion_mani[campania]=A36),Produccion_mani[produccion_tm]))} -> 3230 | E36: {=SUM(IF((Produccion_mani[provincia_nombre]=E$29)*(Produccion_mani[campania]=A36),Produccion_mani[produccion_tm]))} -> 8508 | F36: {=SUM(IF((Produccion_mani[provincia_nombre]=F$29)*(Produccion_mani[campania]=A36),Produccion_mani[produccion_tm]))} -> 18 | G36: {=SUM(IF((Produccion_mani[provincia_nombre]=G$29)*(Produccion_mani[campania]=A36),Produccion_mani[produccion_tm]))} -> 4 | H36: {=SUM(IF((Produccion_mani[provincia_nombre]=H$29)*(Produccion_mani[campania]=A36),Produccion_mani[produccion_tm]))} -> 1265 | I36: {=SUM(IF((Produccion_mani[provincia_nombre]=I$29)*(Produccion_mani[campania]=A36),Produccion_mani[produccion_tm]))} -> 9787 | J36: {=SUM(IF((Produccion_mani[provincia_nombre]=J$29)*(Produccion_mani[campania]=A36),Produccion_mani[produccion_tm]))} -> 67 | K36: {=SUM(IF((Produccion_mani[provincia_nombre]=K$29)*(Produccion_mani[campania]=A36),Produccion_mani[produccion_tm]))} -> 3524 | L36: {=SUM(IF((Produccion_mani[provincia_nombre]=L$29)*(Produccion_mani[campania]=A36),Produccion_mani[produccion_tm]))} -> 0 | M36: {=SUM(IF((Produccion_mani[provincia_nombre]=M$29)*(Produccion_mani[campania]=A36),Produccion_mani[produccion_tm]))} -> 54 | N36: {=SUM(IF((Produccion_mani[provincia_nombre]=N$29)*(Produccion_mani[campania]=A36),Produccion_mani[produccion_tm]))} -> 12 | O36: {=SUM(IF((Produccion_mani[provincia_nombre]=O$29)*(Produccion_mani[campania]=A36),Produccion_mani[produccion_tm]))} -> 14 | P36: {=SUM(IF((Produccion_mani[provincia_nombre]=P$29)*(Produccion_mani[campania]=A36),Produccion_mani[produccion_tm]))} -> 0 | Q36: {=SUM(IF((Produccion_mani[provincia_nombre]=Q$29)*(Produccion_mani[campania]=A36),Produccion_mani[produccion_tm]))} -> 0 | R36: {=SUM(IF((Produccion_mani[provincia_nombre]=R$29)*(Produccion_mani[campania]=A36),Produccion_mani[produccion_tm]))} -> 0 | S36: {=SUM(IF((Produccion_mani[provincia_nombre]=S$29)*(Produccion_mani[campania]=A36),Produccion_mani[produccion_tm]))} -> 0
A37: 1934/1935 | B37: {=SUM(IF((Produccion_mani[provincia_nombre]=B$29)*(Produccion_mani[campania]=A37),Produccion_mani[produccion_tm]))} -> 200 | C37: {=SUM(IF((Produccion_mani[provincia_nombre]=C$29)*(Produccion_mani[campania]=A37),Produccion_mani[produccion_tm]))} -> 59254 | D37: {=SUM(IF((Produccion_mani[provincia_nombre]=D$29)*(Produccion_mani[campania]=A37),Produccion_mani[produccion_tm]))} -> 2400 | E37: {=SUM(IF((Produccion_mani[provincia_nombre]=E$29)*(Produccion_mani[campania]=A37),Produccion_mani[produccion_tm]))} -> 14464 | F37: {=SUM(IF((Produccion_mani[provincia_nombre]=F$29)*(Produccion_mani[campania]=A37),Produccion_mani[produccion_tm]))} -> 63 | G37: {=SUM(IF((Produccion_mani[provincia_nombre]=G$29)*(Produccion_mani[campania]=A37),Produccion_mani[produccion_tm]))} -> 0 | H37: {=SUM(IF((Produccion_mani[provincia_nombre]=H$29)*(Produccion_mani[campania]=A37),Produccion_mani[produccion_tm]))} -> 855 | I37: {=SUM(IF((Produccion_mani[provincia_nombre]=I$29)*(Produccion_mani[campania]=A37),Produccion_mani[produccion_tm]))} -> 14175 | J37: {=SUM(IF((Produccion_mani[provincia_nombre]=J$29)*(Produccion_mani[campania]=A37),Produccion_mani[produccion_tm]))} -> 0 | K37: {=SUM(IF((Produccion_mani[provincia_nombre]=K$29)*(Produccion_mani[campania]=A37),Produccion_mani[produccion_tm]))} -> 1200 | L37: {=SUM(IF((Produccion_mani[provincia_nombre]=L$29)*(Produccion_mani[campania]=A37),Produccion_mani[produccion_tm]))} -> 2 | M37: {=SUM(IF((Produccion_mani[provincia_nombre]=M$29)*(Produccion_mani[campania]=A37),Produccion_mani[produccion_tm]))} -> 35 | N37: {=SUM(IF((Produccion_mani[provincia_nombre]=N$29)*(Produccion_mani[campania]=A37),Produccion_mani[produccion_tm]))} -> 12 | O37: {=SUM(IF((Produccion_mani[provincia_nombre]=O$29)*(Produccion_mani[campania]=A37),Produccion_mani[produccion_tm]))} -> 0 | P37: {=SUM(IF((Produccion_mani[provincia_nombre]=P$29)*(Produccion_mani[campania]=A37),Produccion_mani[produccion_tm]))} -> 112 | Q37: {=SUM(IF((Produccion_mani[provincia_nombre]=Q$29)*(Produccion_mani[campania]=A37),Produccion_mani[produccion_tm]))} -> 0 | R37: {=SUM(IF((Produccion_mani[provincia_nombre]=R$29)*(Produccion_mani[campania]=A37),Produccion_mani[produccion_tm]))} -> 0 | S37: {=SUM(IF((Produccion_mani[provincia_nombre]=S$29)*(Produccion_mani[campania]=A37),Produccion_mani[produccion_tm]))} -> 0
A38: 1935/1936 | B38: {=SUM(IF((Produccion_mani[provincia_nombre]=B$29)*(Produccion_mani[campania]=A38),Produccion_mani[produccion_tm]))} -> 290 | C38: {=SUM(IF((Produccion_mani[provincia_nombre]=C$29)*(Produccion_mani[campania]=A38),Produccion_mani[produccion_tm]))} -> 89370 | D38: {=SUM(IF((Produccion_mani[provincia_nombre]=D$29)*(Produccion_mani[campania]=A38),Produccion_mani[produccion_tm]))} -> 1566 | E38: {=SUM(IF((Produccion_mani[provincia_nombre]=E$29)*(Produccion_mani[campania]=A38),Produccion_mani[produccion_tm]))} -> 2841 | F38: {=SUM(IF((Produccion_mani[provincia_nombre]=F$29)*(Produccion_mani[campania]=A38),Produccion_mani[produccion_tm]))} -> 23 | G38: {=SUM(IF((Produccion_mani[provincia_nombre]=G$29)*(Produccion_mani[campania]=A38),Produccion_mani[produccion_tm]))} -> 3 | H38: {=SUM(IF((Produccion_mani[provincia_nombre]=H$29)*(Produccion_mani[campania]=A38),Produccion_mani[produccion_tm]))} -> 1200 | I38: {=SUM(IF((Produccion_mani[provincia_nombre]=I$29)*(Produccion_mani[campania]=A38),Produccion_mani[produccion_tm]))} -> 15736 | J38: {=SUM(IF((Produccion_mani[provincia_nombre]=J$29)*(Produccion_mani[campania]=A38),Produccion_mani[produccion_tm]))} -> 13 | K38: {=SUM(IF((Produccion_mani[provincia_nombre]=K$29)*(Produccion_mani[campania]=A38),Produccion_mani[produccion_tm]))} -> 2227 | L38: {=SUM(IF((Produccion_mani[provincia_nombre]=L$29)*(Produccion_mani[campania]=A38),Produccion_mani[produccion_tm]))} -> 4 | M38: {=SUM(IF((Produccion_mani[provincia_nombre]=M$29)*(Produccion_mani[campania]=A38),Produccion_mani[produccion_tm]))} -> 45 | N38: {=SUM(IF((Produccion_mani[provincia_nombre]=N$29)*(Produccion_mani[campania]=A38),Produccion_mani[produccion_tm]))} -> 6 | O38: {=SUM(IF((Produccion_mani[provincia_nombre]=O$29)*(Produccion_mani[campania]=A38),Produccion_mani[produccion_tm]))} -> 0 | P38: {=SUM(IF((Produccion_mani[provincia_nombre]=P$29)*(Produccion_mani[campania]=A38),Produccion_mani[produccion_tm]))} -> 184 | Q38: {=SUM(IF((Produccion_mani[provincia_nombre]=Q$29)*(Produccion_mani[campania]=A38),Produccion_mani[produccion_tm]))} -> 0 | R38: {=SUM(IF((Produccion_mani[provincia_nombre]=R$29)*(Produccion_mani[campania]=A38),Produccion_mani[produccion_tm]))} -> 0 | S38: {=SUM(IF((Produccion_mani[provincia_nombre]=S$29)*(Produccion_mani[campania]=A38),Produccion_mani[produccion_tm]))} -> 0
A39: 1936/1937 | B39: {=SUM(IF((Produccion_mani[provincia_nombre]=B$29)*(Produccion_mani[campania]=A39),Produccion_mani[produccion_tm]))} -> 69 | C39: {=SUM(IF((Produccion_mani[provincia_nombre]=C$29)*(Produccion_mani[campania]=A39),Produccion_mani[produccion_tm]))} -> 57965 | D39: {=SUM(IF((Produccion_mani[provincia_nombre]=D$29)*(Produccion_mani[campania]=A39),Produccion_mani[produccion_tm]))} -> 1494 | E39: {=SUM(IF((Produccion_mani[provincia_nombre]=E$29)*(Produccion_mani[campania]=A39),Produccion_mani[produccion_tm]))} -> 4174 | F39: {=SUM(IF((Produccion_mani[provincia_nombre]=F$29)*(Produccion_mani[campania]=A39),Produccion_mani[produccion_tm]))} -> 39 | G39: {=SUM(IF((Produccion_mani[provincia_nombre]=G$29)*(Produccion_mani[campania]=A39),Produccion_mani[produccion_tm]))} -> 5 | H39: {=SUM(IF((Produccion_mani[provincia_nombre]=H$29)*(Produccion_mani[campania]=A39),Produccion_mani[produccion_tm]))} -> 306 | I39: {=SUM(IF((Produccion_mani[provincia_nombre]=I$29)*(Produccion_mani[campania]=A39),Produccion_mani[produccion_tm]))} -> 14456 | J39: {=SUM(IF((Produccion_mani[provincia_nombre]=J$29)*(Produccion_mani[campania]=A39),Produccion_mani[produccion_tm]))} -> 6 | K39: {=SUM(IF((Produccion_mani[provincia_nombre]=K$29)*(Produccion_mani[campania]=A39),Produccion_mani[produccion_tm]))} -> 486 | L39: {=SUM(IF((Produccion_mani[provincia_nombre]=L$29)*(Produccion_mani[campania]=A39),Produccion_mani[produccion_tm]))} -> 0 | M39: {=SUM(IF((Produccion_mani[provincia_nombre]=M$29)*(Produccion_mani[campania]=A39),Produccion_mani[produccion_tm]))} -> 149 | N39: {=SUM(IF((Produccion_mani[provincia_nombre]=N$29)*(Produccion_mani[campania]=A39),Produccion_mani[produccion_tm]))} -> 0 | O39: {=SUM(IF((Produccion_mani[provincia_nombre]=O$29)*(Produccion_mani[campania]=A39),Produccion_mani[produccion_tm]))} -> 86 | P39: {=SUM(IF((Produccion_mani[provincia_nombre]=P$29)*(Produccion_mani[campania]=A39),Produccion_mani[produccion_tm]))} -> 30 | Q39: {=SUM(IF((Produccion_mani[provincia_nombre]=Q$29)*(Produccion_mani[campania]=A39),Produccion_mani[produccion_tm]))} -> 81 | R39: {=SUM(IF((Produccion_mani[provincia_nombre]=R$29)*(Produccion_mani[campania]=A39),Produccion_mani[produccion_tm]))} -> 0 | S39: {=SUM(IF((Produccion_mani[provincia_nombre]=S$29)*(Produccion_mani[campania]=A39),Produccion_mani[produccion_tm]))} -> 0
A40: 1937/1938 | B40: {=SUM(IF((Produccion_mani[provincia_nombre]=B$29)*(Produccion_mani[campania]=A40),Produccion_mani[produccion_tm]))} -> 0 | C40: {=SUM(IF((Produccion_mani[provincia_nombre]=C$29)*(Produccion_mani[campania]=A40),Produccion_mani[produccion_tm]))} -> 42326 | D40: {=SUM(IF((Produccion_mani[provincia_nombre]=D$29)*(Produccion_mani[campania]=A40),Produccion_mani[produccion_tm]))} -> 2351 | E40: {=SUM(IF((Produccion_mani[provincia_nombre]=E$29)*(Produccion_mani[campania]=A40),Produccion_mani[produccion_tm]))} -> 8630 | F40: {=SUM(IF((Produccion_mani[provincia_nombre]=F$29)*(Produccion_mani[campania]=A40),Produccion_mani[produccion_tm]))} -> 0 | G40: {=SUM(IF((Produccion_mani[provincia_nombre]=G$29)*(Produccion_mani[campania]=A40),Produccion_mani[produccion_tm]))} -> 0 | H40: {=SUM(IF((Produccion_mani[provincia_nombre]=H$29)*(Produccion_mani[campania]=A40),Produccion_mani[produccion_tm]))} -> 40 | I40: {=SUM(IF((Produccion_mani[provincia_nombre]=I$29)*(Produccion_mani[campania]=A40),Produccion_mani[produccion_tm]))} -> 14663 | J40: {=SUM(IF((Produccion_mani[provincia_nombre]=J$29)*(Produccion_mani[campania]=A40),Produccion_mani[produccion_tm]))} -> 0 | K40: {=SUM(IF((Produccion_mani[provincia_nombre]=K$29)*(Produccion_mani[campania]=A40),Produccion_mani[produccion_tm]))} -> 1272 | L40: {=SUM(IF((Produccion_mani[provincia_nombre]=L$29)*(Produccion_mani[campania]=A40),Produccion_mani[produccion_tm]))} -> 0 | M40: {=SUM(IF((Produccion_mani[provincia_nombre]=M$29)*(Produccion_mani[campania]=A40),Produccion_mani[produccion_tm]))} -> 0 | N40: {=SUM(IF((Produccion_mani[provincia_nombre]=N$29)*(Produccion_mani[campania]=A40),Produccion_mani[produccion_tm]))} -> 0 | O40: {=SUM(IF((Produccion_mani[provincia_nombre]=O$29)*(Produccion_mani[campania]=A40),Produccion_mani[produccion_tm]))} -> 16 | P40: {=SUM(IF((Produccion_mani[provincia_nombre]=P$29)*(Produccion_mani[campania]=A40),Produccion_mani[produccion_tm]))} -> 19 | Q40: {=SUM(IF((Produccion_mani[provincia_nombre]=Q$29)*(Produccion_mani[campania]=A40),Produccion_mani[produccion_tm]))} -> 0 | R40: {=SUM(IF((Produccion_mani[provincia_nombre]=R$29)*(Produccion_mani[campania]=A40),Produccion_mani[produccion_tm]))} -> 0 | S40: {=SUM(IF((Produccion_mani[provincia_nombre]=S$29)*(Produccion_mani[campania]=A40),Produccion_mani[produccion_tm]))} -> 0
A41: 1938/1939 | B41: {=SUM(IF((Produccion_mani[provincia_nombre]=B$29)*(Produccion_mani[campania]=A41),Produccion_mani[produccion_tm]))} -> 0 | C41: {=SUM(IF((Produccion_mani[provincia_nombre]=C$29)*(Produccion_mani[campania]=A41),Produccion_mani[produccion_tm]))} -> 15641 | D41: {=SUM(IF((Produccion_mani[provincia_nombre]=D$29)*(Produccion_mani[campania]=A41),Produccion_mani[produccion_tm]))} -> 0 | E41: {=SUM(IF((Produccion_mani[provincia_nombre]=E$29)*(Produccion_mani[campania]=A41),Produccion_mani[produccion_tm]))} -> 9963 | F41: {=SUM(IF((Produccion_mani[provincia_nombre]=F$29)*(Produccion_mani[campania]=A41),Produccion_mani[produccion_tm]))} -> 0 | G41: {=SUM(IF((Produccion_mani[provincia_nombre]=G$29)*(Produccion_mani[campania]=A41),Produccion_mani[produccion_tm]))} -> 0 | H41: {=SUM(IF((Produccion_mani[provincia_nombre]=H$29)*(Produccion_mani[campania]=A41),Produccion_mani[produccion_tm]))} -> 309 | I41: {=SUM(IF((Produccion_mani[provincia_nombre]=I$29)*(Produccion_mani[campania]=A41),Produccion_mani[produccion_tm]))} -> 12768 | J41: {=SUM(IF((Produccion_mani[provincia_nombre]=J$29)*(Produccion_mani[campania]=A41),Produccion_mani[produccion_tm]))} -> 0 | K41: {=SUM(IF((Produccion_mani[provincia_nombre]=K$29)*(Produccion_mani[campania]=A41),Produccion_mani[produccion_tm]))} -> 2141 | L41: {=SUM(IF((Produccion_mani[provincia_nombre]=L$29)*(Produccion_mani[campania]=A41),Produccion_mani[produccion_tm]))} -> 0 | M41: {=SUM(IF((Produccion_mani[provincia_nombre]=M$29)*(Produccion_mani[campania]=A41),Produccion_mani[produccion_tm]))} -> 0 | N41: {=SUM(IF((Produccion_mani[provincia_nombre]=N$29)*(Produccion_mani[campania]=A41),Produccion_mani[produccion_tm]))} -> 0 | O41: {=SUM(IF((Produccion_mani[provincia_nombre]=O$29)*(Produccion_mani[campania]=A41),Produccion_mani[produccion_tm]))} -> 0 | P41: {=SUM(IF((Produccion_mani[provincia_nombre]=P$29)*(Produccion_mani[campania]=A41),Produccion_mani[produccion_tm]))} -> 0 | Q41: {=SUM(IF((Produccion_mani[provincia_nombre]=Q$29)*(Produccion_mani[campania]=A41),Produccion_mani[produccion_tm]))} -> 0 | R41: {=SUM(IF((Produccion_mani[provincia_nombre]=R$29)*(Produccion_mani[campania]=A41),Produccion_mani[produccion_tm]))} -> 0 | S41: {=SUM(IF((Produccion_mani[provincia_nombre]=S$29)*(Produccion_mani[campania]=A41),Produccion_mani[produccion_tm]))} -> 0
A42: 1939/1940 | B42: {=SUM(IF((Produccion_mani[provincia_nombre]=B$29)*(Produccion_mani[campania]=A42),Produccion_mani[produccion_tm]))} -> 0 | C42: {=SUM(IF((Produccion_mani[provincia_nombre]=C$29)*(Produccion_mani[campania]=A42),Produccion_mani[produccion_tm]))} -> 53695 | D42: {=SUM(IF((Produccion_mani[provincia_nombre]=D$29)*(Produccion_mani[campania]=A42),Produccion_mani[produccion_tm]))} -> 740 | E42: {=SUM(IF((Produccion_mani[provincia_nombre]=E$29)*(Produccion_mani[campania]=A42),Produccion_mani[produccion_tm]))} -> 12360 | F42: {=SUM(IF((Produccion_mani[provincia_nombre]=F$29)*(Produccion_mani[campania]=A42),Produccion_mani[produccion_tm]))} -> 104 | G42: {=SUM(IF((Produccion_mani[provincia_nombre]=G$29)*(Produccion_mani[campania]=A42),Produccion_mani[produccion_tm]))} -> 0 | H42: {=SUM(IF((Produccion_mani[provincia_nombre]=H$29)*(Produccion_mani[campania]=A42),Produccion_mani[produccion_tm]))} -> 36 | I42: {=SUM(IF((Produccion_mani[provincia_nombre]=I$29)*(Produccion_mani[campania]=A42),Produccion_mani[produccion_tm]))} -> 14660 | J42: {=SUM(IF((Produccion_mani[provincia_nombre]=J$29)*(Produccion_mani[campania]=A42),Produccion_mani[produccion_tm]))} -> 130 | K42: {=SUM(IF((Produccion_mani[provincia_nombre]=K$29)*(Produccion_mani[campania]=A42),Produccion_mani[produccion_tm]))} -> 2200 | L42: {=SUM(IF((Produccion_mani[provincia_nombre]=L$29)*(Produccion_mani[campania]=A42),Produccion_mani[produccion_tm]))} -> 0 | M42: {=SUM(IF((Produccion_mani[provincia_nombre]=M$29)*(Produccion_mani[campania]=A42),Produccion_mani[produccion_tm]))} -> 474 | N42: {=SUM(IF((Produccion_mani[provincia_nombre]=N$29)*(Produccion_mani[campania]=A42),Produccion_mani[produccion_tm]))} -> 0 | O42: {=SUM(IF((Produccion_mani[provincia_nombre]=O$29)*(Produccion_mani[campania]=A42),Produccion_mani[produccion_tm]))} -> 0 | P42: {=SUM(IF((Produccion_mani[provincia_nombre]=P$29)*(Produccion_mani[campania]=A42),Produccion_mani[produccion_tm]))} -> 0 | Q42: {=SUM(IF((Produccion_mani[provincia_nombre]=Q$29)*(Produccion_mani[campania]=A42),Produccion_mani[produccion_tm]))} -> 0 | R42: {=SUM(IF((Produccion_mani[provincia_nombre]=R$29)*(Produccion_mani[campania]=A42),Produccion_mani[produccion_tm]))} -> 0 | S42: {=SUM(IF((Produccion_mani[provincia_nombre]=S$29)*(Produccion_mani[campania]=A42),Produccion_mani[produccion_tm]))} -> 0
... A127: 2024/2025 | B127: {=SUM(IF((Produccion_mani[provincia_nombre]=B$29)*(Produccion_mani[campania]=A127),Produccion_mani[produccion_tm]))} -> 0 | C127: {=SUM(IF((Produccion_mani[provincia_nombre]=C$29)*(Produccion_mani[campania]=A127),Produccion_mani[produccion_tm]))} -> 1268363 | D127: {=SUM(IF((Produccion_mani[provincia_nombre]=D$29)*(Produccion_mani[campania]=A127),Produccion_mani[produccion_tm]))} -> 0 | E127: {=SUM(IF((Produccion_mani[provincia_nombre]=E$29)*(Produccion_mani[campania]=A127),Produccion_mani[produccion_tm]))} -> 0 | F127: {=SUM(IF((Produccion_mani[provincia_nombre]=F$29)*(Produccion_mani[campania]=A127),Produccion_mani[produccion_tm]))} -> 0 | G127: {=SUM(IF((Produccion_mani[provincia_nombre]=G$29)*(Produccion_mani[campania]=A127),Produccion_mani[produccion_tm]))} -> 520 | H127: {=SUM(IF((Produccion_mani[provincia_nombre]=H$29)*(Produccion_mani[campania]=A127),Produccion_mani[produccion_tm]))} -> 0 | I127: {=SUM(IF((Produccion_mani[provincia_nombre]=I$29)*(Produccion_mani[campania]=A127),Produccion_mani[produccion_tm]))} -> 51170 | J127: {=SUM(IF((Produccion_mani[provincia_nombre]=J$29)*(Produccion_mani[campania]=A127),Produccion_mani[produccion_tm]))} -> 627 | K127: {=SUM(IF((Produccion_mani[provincia_nombre]=K$29)*(Produccion_mani[campania]=A127),Produccion_mani[produccion_tm]))} -> 3899 | L127: {=SUM(IF((Produccion_mani[provincia_nombre]=L$29)*(Produccion_mani[campania]=A127),Produccion_mani[produccion_tm]))} -> 2280 | M127: {=SUM(IF((Produccion_mani[provincia_nombre]=M$29)*(Produccion_mani[campania]=A127),Produccion_mani[produccion_tm]))} -> 2593 | N127: {=SUM(IF((Produccion_mani[provincia_nombre]=N$29)*(Produccion_mani[campania]=A127),Produccion_mani[produccion_tm]))} -> 0 | O127: {=SUM(IF((Produccion_mani[provincia_nombre]=O$29)*(Produccion_mani[campania]=A127),Produccion_mani[produccion_tm]))} -> 36338 | P127: {=SUM(IF((Produccion_mani[provincia_nombre]=P$29)*(Produccion_mani[campania]=A127),Produccion_mani[produccion_tm]))} -> 0 | Q127: {=SUM(IF((Produccion_mani[provincia_nombre]=Q$29)*(Produccion_mani[campania]=A127),Produccion_mani[produccion_tm]))} -> 315761 | R127: {=SUM(IF((Produccion_mani[provincia_nombre]=R$29)*(Produccion_mani[campania]=A127),Produccion_mani[produccion_tm]))} -> 127986 | S127: {=SUM(IF((Produccion_mani[provincia_nombre]=S$29)*(Produccion_mani[campania]=A127),Produccion_mani[produccion_tm]))} -> 0
A128: MAXIMO | B128: =MAX(B30:B127) -> 3775 | C128: =MAX(C30:C127) -> 1268363 | D128: =MAX(D30:D127) -> 5475 | E128: =MAX(E30:E127) -> 14464 | F128: =MAX(F30:F127) -> 3295 | G128: =MAX(G30:G127) -> 1600 | H128: =MAX(H30:H127) -> 1492 | I128: =MAX(I30:I127) -> 51170 | ... S128: =MAX(S30:S127) -> 0
A129: CAMPAÑA | B129: {=_xlfn.TAKE((_xlfn._xlws.FILTER(_xlfn.ANCHORARRAY($A30),B$30:B$127=B128)),1)} -> 1927/1928 | C129: {=_xlfn.TAKE((_xlfn._xlws.FILTER(_xlfn.ANCHORARRAY($A30),C$30:C$127=C128)),1)} -> 2024/2025 | D129: {=_xlfn.TAKE((_xlfn._xlws.FILTER(_xlfn.ANCHORARRAY($A30),D$30:D$127=D128)),1)} -> 1946/1947 | E129: {=_xlfn.TAKE((_xlfn._xlws.FILTER(_xlfn.ANCHORARRAY($A30),E$30:E$127=E128)),1)} -> 1934/1935 | F129: {=_xlfn.TAKE((_xlfn._xlws.FILTER(_xlfn.ANCHORARRAY($A30),F$30:F$127=F128)),1)} -> 2006/2007 | G129: {=_xlfn.TAKE((_xlfn._xlws.FILTER(_xlfn.ANCHORARRAY($A30),G$30:G$127=G128)),1)} -> 2004/2005 | H129: {=_xlfn.TAKE((_xlfn._xlws.FILTER(_xlfn.ANCHORARRAY($A30),H$30:H$127=H128)),1)} -> 1931/1932 | I129: {=_xlfn.TAKE((_xlfn._xlws.FILTER(_xlfn.ANCHORARRAY($A30),I$30:I$127=I128)),1)} -> 2024/2025 | ... S129: {=_xlfn.TAKE((_xlfn._xlws.FILTER(_xlfn.ANCHORARRAY($A30),S$30:S$127=S128)),1)} -> 1927/1928
A132: Chaco | B132: Córdoba | C132: Corrientes | D132: Entre Ríos | E132: Formosa | F132: Jujuy | G132: Misiones | H132: Santa Fe | I132: Santiago del Estero | J132: Tucumán | K132: Catamarca | L132: Salta | M132: San Juan | N132: San Luis | O132: Mendoza | P132: Buenos Aires | Q132: La Pampa | R132: La Rioja
